<sdf version='1.4'>
  <world name='default'>
    <model name='ground_plane'>
      <static>1</static>
      <link name='link'>
        <collision name='collision'>
          <geometry>
            <plane>
              <normal>0 0 1</normal>
              <size>100 100</size>
            </plane>
          </geometry>
          <surface>
            <friction>
              <ode>
                <mu>100</mu>
                <mu2>50</mu2>
              </ode>
            </friction>
            <bounce/>
            <contact>
              <ode/>
            </contact>
          </surface>
          <max_contacts>10</max_contacts>
        </collision>
        <visual name='visual'>
          <cast_shadows>0</cast_shadows>
          <geometry>
            <plane>
              <normal>0 0 1</normal>
              <size>100 100</size>
            </plane>
          </geometry>
          <material>
            <script>
              <uri>file://media/materials/scripts/gazebo.material</uri>
              <name>Gazebo/Grey</name>
            </script>
          </material>
        </visual>
        <velocity_decay>
          <linear>0</linear>
          <angular>0</angular>
        </velocity_decay>
        <self_collide>0</self_collide>
        <kinematic>0</kinematic>
        <gravity>1</gravity>
      </link>
    </model>
    <light name='sun' type='directional'>
      <cast_shadows>1</cast_shadows>
      <pose>0 0 10 0 -0 0</pose>
      <diffuse>0.8 0.8 0.8 1</diffuse>
      <specular>0.2 0.2 0.2 1</specular>
      <attenuation>
        <range>1000</range>
        <constant>0.9</constant>
        <linear>0.01</linear>
        <quadratic>0.001</quadratic>
      </attenuation>
      <direction>-0.5 0.1 -0.9</direction>
    </light>
    <gui fullscreen='0'>
      <camera name='user_camera'>
        <pose>2.06775 -28.0388 46.8213 1.7089e-16 0.863645 1.54019</pose>
        <view_controller>orbit</view_controller>
      </camera>
    </gui>
    <physics type='ode'>
      <max_step_size>0.001</max_step_size>
      <real_time_factor>1</real_time_factor>
      <real_time_update_rate>1000</real_time_update_rate>
      <gravity>0 0 -9.8</gravity>
    </physics>
    <scene>
      <ambient>0.4 0.4 0.4 1</ambient>
      <background>0.7 0.7 0.7 1</background>
      <shadows>1</shadows>
    </scene>
    <spherical_coordinates>
      <surface_model>EARTH_WGS84</surface_model>
      <latitude_deg>0</latitude_deg>
      <longitude_deg>0</longitude_deg>
      <elevation>0</elevation>
      <heading_deg>0</heading_deg>
    </spherical_coordinates>
    <model name='willowgarage'>
      <static>1</static>
      <pose>10 7 0 0 -0 0</pose>
      <link name='walls'>
        <collision name='collision'>
          <geometry>
            <mesh>
              <uri>model://willowgarage/meshes/willowgarage_collision.dae</uri>
            </mesh>
          </geometry>
          <max_contacts>10</max_contacts>
          <surface>
            <bounce/>
            <friction>
              <ode/>
            </friction>
            <contact>
              <ode/>
            </contact>
          </surface>
        </collision>
        <visual name='visual'>
          <geometry>
            <mesh>
              <uri>model://willowgarage/meshes/willowgarage_visual.dae</uri>
            </mesh>
          </geometry>
          <cast_shadows>0</cast_shadows>
        </visual>
        <velocity_decay>
          <linear>0</linear>
          <angular>0</angular>
        </velocity_decay>
        <self_collide>0</self_collide>
        <kinematic>0</kinematic>
        <gravity>1</gravity>
      </link>
    </model>
    <state world_name='default'>
      <sim_time>530 978000000</sim_time>
      <real_time>160 114372003</real_time>
      <wall_time>1542957314 936532222</wall_time>
      <model name='ground_plane'>
        <pose>0 0 0 0 -0 0</pose>
        <link name='link'>
          <pose>0 0 0 0 -0 0</pose>
          <velocity>0 0 0 0 -0 0</velocity>
          <acceleration>0 0 0 0 -0 0</acceleration>
          <wrench>0 0 0 0 -0 0</wrench>
        </link>
      </model>
      <model name='tracked'>
        <pose>16.083 14.9486 0.049991 6.2e-05 2.11758e-22 0.026255</pose>
        <link name='FL'>
          <pose>16.1788 15.1112 0.050001 6.2e-05 0.000169 0.026255</pose>
          <velocity>0.00012 0.002797 0.011776 0.082801 0.226807 -4e-05</velocity>
          <acceleration>0 0 0 0 -0 0</acceleration>
          <wrench>0 0 0 0 -0 0</wrench>
        </link>
        <link name='FR'>
          <pose>16.1872 14.7913 0.049981 6.3e-05 -0.0001 0.026255</pose>
          <velocity>0.000102 0.002797 -0.016627 0.092361 -0.139633 -3.9e-05</velocity>
          <acceleration>0 0 0 0 -0 0</acceleration>
          <wrench>0 0 0 0 -0 0</wrench>
        </link>
        <link name='RL'>
          <pose>15.9788 15.1059 0.050001 6.2e-05 -0.000177 0.026255</pose>
          <velocity>0.000114 0.002807 0.011775 0.094719 -0.228603 -5.3e-05</velocity>
          <acceleration>0 0 0 0 -0 0</acceleration>
          <wrench>0 0 0 0 -0 0</wrench>
        </link>
        <link name='RR'>
          <pose>15.9872 14.786 0.049981 6.2e-05 0.0001 0.026255</pose>
          <velocity>0.000103 0.00281 -0.016626 0.084955 0.14429 -3.7e-05</velocity>
          <acceleration>0 0 0 0 -0 0</acceleration>
          <wrench>0 0 0 0 -0 0</wrench>
        </link>
        <link name='base'>
          <pose>16.083 14.9486 0.049991 6.2e-05 2.11758e-22 0.026255</pose>
          <velocity>0.000112 0.002803 -0.002426 0.088733 0.002328 -3.5e-05</velocity>
          <acceleration>0 0 0 0 -0 0</acceleration>
          <wrench>0 0 0 0 -0 0</wrench>
        </link>
        <link name='link2'>
          <pose>16.083 14.9486 0.174991 8.6e-05 0.523576 0.028699</pose>
          <velocity>0.000336 -0.008064 -0.002419 0.086586 -0.007016 -0.00583</velocity>
          <acceleration>0 0 0 0 -0 0</acceleration>
          <wrench>0 0 0 0 -0 0</wrench>
        </link>
        <link name='link3'>
          <pose>16.3141 14.9552 0.071092 0.000109 0.155296 0.028665</pose>
          <velocity>0.004118 0.000659 -0.003552 0.076362 0.024188 -0.003831</velocity>
          <acceleration>0 0 0 0 -0 0</acceleration>
          <wrench>0 0 0 0 -0 0</wrench>
        </link>
        <link name='m2'>
          <pose>16.083 14.9486 0.149991 5.6e-05 -1e-06 0.028657</pose>
          <velocity>0.00034 -0.005791 -0.002433 0.090017 0.002492 -0.005977</velocity>
          <acceleration>0 0 0 0 -0 0</acceleration>
          <wrench>0 0 0 0 -0 0</wrench>
        </link>
        <link name='m4'>
          <pose>16.6083 14.9637 0.026507 0.000102 0.139655 0.028661</pose>
          <velocity>-0.00374 0.002834 -0.004206 0.078231 -0.026291 -0.00365</velocity>
          <acceleration>0 0 0 0 -0 0</acceleration>
          <wrench>0 0 0 0 -0 0</wrench>
        </link>
      </model>
      <model name='willowgarage'>
        <pose>-10.6368 2.48626 0 0 -0 0</pose>
        <link name='walls'>
          <pose>-10.6368 2.48626 0 0 -0 0</pose>
          <velocity>0 0 0 0 -0 0</velocity>
          <acceleration>0 0 0 0 -0 0</acceleration>
          <wrench>0 0 0 0 -0 0</wrench>
        </link>
      </model>
    </state>
    <model name='tracked'>
      <link name='base'>
        <pose>0 0 0 0 -0 0</pose>
        <inertial>
          <pose>0 0 0.00241935 0 -0 0</pose>
          <mass>31</mass>
          <inertia>
            <ixx>0.225589</ixx>
            <ixy>0</ixy>
            <ixz>0</ixz>
            <iyy>0.233624</iyy>
            <iyz>0</iyz>
            <izz>0.400302</izz>
          </inertia>
        </inertial>
        <collision name='base_collision'>
          <pose>0 0 0 0 -0 0</pose>
          <geometry>
            <mesh>
              <scale>1 1 1</scale>
              <uri>/home/sato/kitani_ws/src/sne_rollover_recovery/tracked_robot/tracked_description/meshes/main_a.stl</uri>
            </mesh>
          </geometry>
          <surface>
            <contact>
              <ode/>
            </contact>
            <friction>
              <ode>
                <mu>0.2</mu>
                <mu2>0.2</mu2>
              </ode>
            </friction>
            <bounce/>
          </surface>
          <max_contacts>10</max_contacts>
        </collision>
        <collision name='base_collision_m1'>
          <pose>0 0 0.075 0 -0 0</pose>
          <geometry>
            <mesh>
              <scale>1 1 1</scale>
              <uri>/home/sato/kitani_ws/src/sne_rollover_recovery/tracked_robot/tracked_description/meshes/motor_a.stl</uri>
            </mesh>
          </geometry>
          <surface>
            <contact>
              <ode/>
            </contact>
            <friction>
              <ode>
                <mu>0.2</mu>
                <mu2>0.2</mu2>
              </ode>
            </friction>
            <bounce/>
          </surface>
          <surface>
            <contact>
              <ode/>
            </contact>
            <friction>
              <ode>
                <mu>0.2</mu>
                <mu2>0.2</mu2>
              </ode>
            </friction>
          </surface>
          <max_contacts>10</max_contacts>
        </collision>
        <visual name='base_visual'>
          <pose>0 0 0 0 -0 0</pose>
          <geometry>
            <mesh>
              <scale>1 1 1</scale>
              <uri>/home/sato/kitani_ws/src/sne_rollover_recovery/tracked_robot/tracked_description/meshes/main_a.stl</uri>
            </mesh>
          </geometry>
          <material>
            <script>
              <name>Gazebo/Grey</name>
              <uri>__default__</uri>
            </script>
          </material>
        </visual>
        <visual name='base_visual_hokuyo'>
          <pose>0.0866667 0 0.08 0 -0 0</pose>
          <geometry>
            <mesh>
              <scale>1 1 1</scale>
              <uri>/home/sato/kitani_ws/src/sne_rollover_recovery/tracked_robot/tracked_description/meshes/hokuyo.dae</uri>
            </mesh>
          </geometry>
        </visual>
        <visual name='base_visual_m1'>
          <pose>0 0 0.075 0 -0 0</pose>
          <geometry>
            <mesh>
              <scale>1 1 1</scale>
              <uri>/home/sato/kitani_ws/src/sne_rollover_recovery/tracked_robot/tracked_description/meshes/motor_a.stl</uri>
            </mesh>
          </geometry>
          <material>
            <script>
              <name>Gazebo/Grey</name>
              <uri>__default__</uri>
            </script>
          </material>
        </visual>
        <velocity_decay>
          <linear>0</linear>
          <angular>0</angular>
        </velocity_decay>
        <velocity_decay>
          <linear>0</linear>
          <angular>0</angular>
        </velocity_decay>
        <sensor name='head_hokuyo_sensor' type='gpu_ray'>
          <visualize>0</visualize>
          <update_rate>40</update_rate>
          <ray>
            <scan>
              <horizontal>
                <samples>720</samples>
                <resolution>1</resolution>
                <min_angle>-1.5708</min_angle>
                <max_angle>1.5708</max_angle>
              </horizontal>
            </scan>
            <range>
              <min>0.1</min>
              <max>30</max>
              <resolution>0.01</resolution>
            </range>
            <noise>
              <type>gaussian</type>
              <mean>0</mean>
              <stddev>0.01</stddev>
            </noise>
          </ray>
          <plugin name='gazebo_ros_head_hokuyo_controller' filename='libgazebo_ros_gpu_laser.so'>
            <topicName>/tracked/laser/scan</topicName>
            <frameName>hokuyo</frameName>
            <robotNamespace>/</robotNamespace>
          </plugin>
          <pose>0.0866667 0 0.08 0 -0 0</pose>
        </sensor>
        <gravity>1</gravity>
        <velocity_decay>
          <linear>0</linear>
          <angular>0</angular>
        </velocity_decay>
        <self_collide>0</self_collide>
        <kinematic>0</kinematic>
      </link>
      <link name='FL'>
        <pose>0.1 0.16 0 0 -0 0</pose>
        <inertial>
          <pose>0.1 0 0 0 -0 0</pose>
          <mass>1</mass>
          <inertia>
            <ixx>0.000907922</ixx>
            <ixy>0</ixy>
            <ixz>0</ixz>
            <iyy>0.00736067</iyy>
            <iyz>0</iyz>
            <izz>0.00671941</izz>
          </inertia>
        </inertial>
        <collision name='FL_collision'>
          <pose>0.1 0 0 0 -0 0</pose>
          <geometry>
            <mesh>
              <scale>1 1 1</scale>
              <uri>/home/sato/kitani_ws/src/sne_rollover_recovery/tracked_robot/tracked_description/meshes/flipper_a.stl</uri>
            </mesh>
          </geometry>
          <surface>
            <contact>
              <ode/>
            </contact>
            <friction>
              <ode>
                <mu>0.2</mu>
                <mu2>0.2</mu2>
              </ode>
            </friction>
            <bounce/>
          </surface>
          <max_contacts>10</max_contacts>
        </collision>
        <visual name='FL_visual'>
          <pose>0.1 0 0 0 -0 0</pose>
          <geometry>
            <mesh>
              <scale>1 1 1</scale>
              <uri>/home/sato/kitani_ws/src/sne_rollover_recovery/tracked_robot/tracked_description/meshes/flipper_a.stl</uri>
            </mesh>
          </geometry>
          <material>
            <script>
              <name>Gazebo/Blue</name>
              <uri>__default__</uri>
            </script>
          </material>
        </visual>
        <gravity>1</gravity>
        <velocity_decay>
          <linear>0</linear>
          <angular>0</angular>
        </velocity_decay>
        <self_collide>0</self_collide>
        <kinematic>0</kinematic>
      </link>
      <joint name='base2FL' type='revolute'>
        <child>FL</child>
        <parent>base</parent>
        <axis>
          <xyz>0 1 0</xyz>
          <limit>
            <lower>-1e+16</lower>
            <upper>1e+16</upper>
          </limit>
          <dynamics>
            <damping>0.7</damping>
          </dynamics>
        </axis>
      </joint>
      <link name='FR'>
        <pose>0.1 -0.16 0 0 -0 0</pose>
        <inertial>
          <pose>0.1 0 0 0 -0 0</pose>
          <mass>1</mass>
          <inertia>
            <ixx>0.000907922</ixx>
            <ixy>0</ixy>
            <ixz>0</ixz>
            <iyy>0.00736067</iyy>
            <iyz>0</iyz>
            <izz>0.00671941</izz>
          </inertia>
        </inertial>
        <collision name='FR_collision'>
          <pose>0.1 0 0 0 -0 0</pose>
          <geometry>
            <mesh>
              <scale>1 1 1</scale>
              <uri>/home/sato/kitani_ws/src/sne_rollover_recovery/tracked_robot/tracked_description/meshes/flipper_a.stl</uri>
            </mesh>
          </geometry>
          <surface>
            <contact>
              <ode/>
            </contact>
            <friction>
              <ode>
                <mu>0.2</mu>
                <mu2>0.2</mu2>
              </ode>
            </friction>
            <bounce/>
          </surface>
          <max_contacts>10</max_contacts>
        </collision>
        <visual name='FR_visual'>
          <pose>0.1 0 0 0 -0 0</pose>
          <geometry>
            <mesh>
              <scale>1 1 1</scale>
              <uri>/home/sato/kitani_ws/src/sne_rollover_recovery/tracked_robot/tracked_description/meshes/flipper_a.stl</uri>
            </mesh>
          </geometry>
          <material>
            <script>
              <name>Gazebo/Blue</name>
              <uri>__default__</uri>
            </script>
          </material>
        </visual>
        <gravity>1</gravity>
        <velocity_decay>
          <linear>0</linear>
          <angular>0</angular>
        </velocity_decay>
        <self_collide>0</self_collide>
        <kinematic>0</kinematic>
      </link>
      <joint name='base2FR' type='revolute'>
        <child>FR</child>
        <parent>base</parent>
        <axis>
          <xyz>0 1 0</xyz>
          <limit>
            <lower>-1e+16</lower>
            <upper>1e+16</upper>
          </limit>
          <dynamics>
            <damping>0.7</damping>
          </dynamics>
        </axis>
      </joint>
      <link name='RL'>
        <pose>-0.1 0.16 0 0 -0 0</pose>
        <inertial>
          <pose>-0.1 0 0 0 -0 0</pose>
          <mass>1</mass>
          <inertia>
            <ixx>0.000907922</ixx>
            <ixy>0</ixy>
            <ixz>0</ixz>
            <iyy>0.00736067</iyy>
            <iyz>0</iyz>
            <izz>0.00671941</izz>
          </inertia>
        </inertial>
        <collision name='RL_collision'>
          <pose>-0.1 0 0 0 -0 0</pose>
          <geometry>
            <mesh>
              <scale>1 1 1</scale>
              <uri>/home/sato/kitani_ws/src/sne_rollover_recovery/tracked_robot/tracked_description/meshes/flipper_a.stl</uri>
            </mesh>
          </geometry>
          <surface>
            <contact>
              <ode/>
            </contact>
            <friction>
              <ode>
                <mu>0.2</mu>
                <mu2>0.2</mu2>
              </ode>
            </friction>
            <bounce/>
          </surface>
          <max_contacts>10</max_contacts>
        </collision>
        <visual name='RL_visual'>
          <pose>-0.1 0 0 0 -0 0</pose>
          <geometry>
            <mesh>
              <scale>1 1 1</scale>
              <uri>/home/sato/kitani_ws/src/sne_rollover_recovery/tracked_robot/tracked_description/meshes/flipper_a.stl</uri>
            </mesh>
          </geometry>
          <material>
            <script>
              <name>Gazebo/Blue</name>
              <uri>__default__</uri>
            </script>
          </material>
        </visual>
        <gravity>1</gravity>
        <velocity_decay>
          <linear>0</linear>
          <angular>0</angular>
        </velocity_decay>
        <self_collide>0</self_collide>
        <kinematic>0</kinematic>
      </link>
      <joint name='base2RL' type='revolute'>
        <child>RL</child>
        <parent>base</parent>
        <axis>
          <xyz>0 1 0</xyz>
          <limit>
            <lower>-1e+16</lower>
            <upper>1e+16</upper>
          </limit>
          <dynamics>
            <damping>0.7</damping>
          </dynamics>
        </axis>
      </joint>
      <link name='RR'>
        <pose>-0.1 -0.16 0 0 -0 0</pose>
        <inertial>
          <pose>-0.1 0 0 0 -0 0</pose>
          <mass>1</mass>
          <inertia>
            <ixx>0.000907922</ixx>
            <ixy>0</ixy>
            <ixz>0</ixz>
            <iyy>0.00736067</iyy>
            <iyz>0</iyz>
            <izz>0.00671941</izz>
          </inertia>
        </inertial>
        <collision name='RR_collision'>
          <pose>-0.1 0 0 0 -0 0</pose>
          <geometry>
            <mesh>
              <scale>1 1 1</scale>
              <uri>/home/sato/kitani_ws/src/sne_rollover_recovery/tracked_robot/tracked_description/meshes/flipper_a.stl</uri>
            </mesh>
          </geometry>
          <surface>
            <contact>
              <ode/>
            </contact>
            <friction>
              <ode>
                <mu>0.2</mu>
                <mu2>0.2</mu2>
              </ode>
            </friction>
            <bounce/>
          </surface>
          <max_contacts>10</max_contacts>
        </collision>
        <visual name='RR_visual'>
          <pose>-0.1 0 0 0 -0 0</pose>
          <geometry>
            <mesh>
              <scale>1 1 1</scale>
              <uri>/home/sato/kitani_ws/src/sne_rollover_recovery/tracked_robot/tracked_description/meshes/flipper_a.stl</uri>
            </mesh>
          </geometry>
          <material>
            <script>
              <name>Gazebo/Blue</name>
              <uri>__default__</uri>
            </script>
          </material>
        </visual>
        <gravity>1</gravity>
        <velocity_decay>
          <linear>0</linear>
          <angular>0</angular>
        </velocity_decay>
        <self_collide>0</self_collide>
        <kinematic>0</kinematic>
      </link>
      <joint name='base2RR' type='revolute'>
        <child>RR</child>
        <parent>base</parent>
        <axis>
          <xyz>0 1 0</xyz>
          <limit>
            <lower>-1e+16</lower>
            <upper>1e+16</upper>
          </limit>
          <dynamics>
            <damping>0.7</damping>
          </dynamics>
        </axis>
      </joint>
      <link name='m2'>
        <pose>0 0 0.1 0 -0 0</pose>
        <inertial>
          <pose>0 0 0.0499975 1.5708 -0 0</pose>
          <mass>1.0001</mass>
          <inertia>
            <ixx>0.00100798</ixx>
            <ixy>0</ixy>
            <ixz>0</ixz>
            <iyy>0.00746067</iyy>
            <iyz>-3.06006e-19</iyz>
            <izz>0.00681948</izz>
          </inertia>
        </inertial>
        <collision name='m2_collision'>
          <pose>0 0 0.05 1.5708 -0 0</pose>
          <geometry>
            <mesh>
              <scale>1 1 1</scale>
              <uri>/home/sato/kitani_ws/src/sne_rollover_recovery/tracked_robot/tracked_description/meshes/motor_a.stl</uri>
            </mesh>
          </geometry>
          <surface>
            <contact>
              <ode/>
            </contact>
            <friction>
              <ode>
                <mu>0.2</mu>
                <mu2>0.2</mu2>
              </ode>
            </friction>
            <bounce/>
          </surface>
          <max_contacts>10</max_contacts>
        </collision>
        <collision name='m2_collision_m2_center'>
          <pose>0 0 0.025 1.5708 -0 0</pose>
          <geometry>
            <mesh>
              <scale>1 1 1</scale>
              <uri>/home/sato/kitani_ws/src/sne_rollover_recovery/tracked_robot/tracked_description/meshes/motor_a.stl</uri>
            </mesh>
          </geometry>
          <surface>
            <contact>
              <ode/>
            </contact>
            <friction>
              <ode>
                <mu>0.2</mu>
                <mu2>0.2</mu2>
              </ode>
            </friction>
            <bounce/>
          </surface>
          <max_contacts>10</max_contacts>
        </collision>
        <visual name='m2_visual'>
          <pose>0 0 0.025 1.5708 -0 0</pose>
          <geometry>
            <mesh>
              <scale>1 1 1</scale>
              <uri>/home/sato/kitani_ws/src/sne_rollover_recovery/tracked_robot/tracked_description/meshes/motor_a.stl</uri>
            </mesh>
          </geometry>
          <material>
            <script>
              <name>Gazebo/Grey</name>
              <uri>__default__</uri>
            </script>
          </material>
        </visual>
        <visual name='m2_visual_m2_center'>
          <pose>0 0 0.025 1.5708 -0 0</pose>
          <geometry>
            <mesh>
              <scale>1 1 1</scale>
              <uri>/home/sato/kitani_ws/src/sne_rollover_recovery/tracked_robot/tracked_description/meshes/motor_a.stl</uri>
            </mesh>
          </geometry>
          <material>
            <script>
              <name>Gazebo/Grey</name>
              <uri>__default__</uri>
            </script>
          </material>
        </visual>
        <gravity>1</gravity>
        <velocity_decay>
          <linear>0</linear>
          <angular>0</angular>
        </velocity_decay>
        <self_collide>0</self_collide>
        <kinematic>0</kinematic>
      </link>
      <joint name='m1_2m2' type='revolute'>
        <child>m2</child>
        <parent>base</parent>
        <axis>
          <xyz>0 0 1</xyz>
          <limit>
            <lower>-1e+16</lower>
            <upper>1e+16</upper>
          </limit>
          <dynamics>
            <damping>0.7</damping>
          </dynamics>
        </axis>
      </joint>
      <link name='link2'>
        <pose>0 0 0.125 0 -0 0</pose>
        <inertial>
          <pose>0.225 0 0 0 -0 0</pose>
          <mass>2</mass>
          <inertia>
            <ixx>0.00181584</ixx>
            <ixy>0</ixy>
            <ixz>0</ixz>
            <iyy>0.0253301</iyy>
            <iyz>3.13997e-15</iyz>
            <izz>0.0253301</izz>
          </inertia>
        </inertial>
        <collision name='link2_collision'>
          <pose>0.15 0 0 0 -0 0</pose>
          <geometry>
            <mesh>
              <scale>1 1 1</scale>
              <uri>/home/sato/kitani_ws/src/sne_rollover_recovery/tracked_robot/tracked_description/meshes/link1_a.stl</uri>
            </mesh>
          </geometry>
          <surface>
            <contact>
              <ode/>
            </contact>
            <friction>
              <ode>
                <mu>0.2</mu>
                <mu2>0.2</mu2>
              </ode>
            </friction>
            <bounce/>
          </surface>
          <max_contacts>10</max_contacts>
        </collision>
        <collision name='link2_collision_m3'>
          <pose>0.3 0 0 1.5708 -0 0</pose>
          <geometry>
            <mesh>
              <scale>1 1 1</scale>
              <uri>/home/sato/kitani_ws/src/sne_rollover_recovery/tracked_robot/tracked_description/meshes/motor_a.stl</uri>
            </mesh>
          </geometry>
          <surface>
            <contact>
              <ode/>
            </contact>
            <friction>
              <ode>
                <mu>0.2</mu>
                <mu2>0.2</mu2>
              </ode>
            </friction>
            <bounce/>
          </surface>
          <surface>
            <contact>
              <ode/>
            </contact>
            <friction>
              <ode>
                <mu>0.2</mu>
                <mu2>0.2</mu2>
              </ode>
            </friction>
          </surface>
          <max_contacts>10</max_contacts>
        </collision>
        <visual name='link2_visual'>
          <pose>0.15 0 0 0 -0 0</pose>
          <geometry>
            <mesh>
              <scale>1 1 1</scale>
              <uri>/home/sato/kitani_ws/src/sne_rollover_recovery/tracked_robot/tracked_description/meshes/link1_a.stl</uri>
            </mesh>
          </geometry>
          <material>
            <script>
              <name>Gazebo/Grey</name>
              <uri>__default__</uri>
            </script>
          </material>
        </visual>
        <visual name='link2_visual_m3'>
          <pose>0.3 0 0 1.5708 -0 0</pose>
          <geometry>
            <mesh>
              <scale>1 1 1</scale>
              <uri>/home/sato/kitani_ws/src/sne_rollover_recovery/tracked_robot/tracked_description/meshes/motor_a.stl</uri>
            </mesh>
          </geometry>
          <material>
            <script>
              <name>Gazebo/Grey</name>
              <uri>__default__</uri>
            </script>
          </material>
        </visual>
        <velocity_decay>
          <linear>0</linear>
          <angular>0</angular>
        </velocity_decay>
        <gravity>1</gravity>
        <velocity_decay>
          <linear>0</linear>
          <angular>0</angular>
        </velocity_decay>
        <self_collide>0</self_collide>
        <kinematic>0</kinematic>
      </link>
      <joint name='m2_center2link2' type='revolute'>
        <child>link2</child>
        <parent>m2</parent>
        <axis>
          <xyz>0 1 0</xyz>
          <limit>
            <lower>-1e+16</lower>
            <upper>1e+16</upper>
          </limit>
          <dynamics>
            <damping>0.7</damping>
          </dynamics>
        </axis>
      </joint>
      <link name='link3'>
        <pose>0.3 0 0.125 0 -0 0</pose>
        <inertial>
          <pose>0.15 0 0 0 -0 0</pose>
          <mass>1</mass>
          <inertia>
            <ixx>0.000907922</ixx>
            <ixy>0</ixy>
            <ixz>0</ixz>
            <iyy>0.00736067</iyy>
            <iyz>0</iyz>
            <izz>0.00671941</izz>
          </inertia>
        </inertial>
        <collision name='link3_collision'>
          <pose>0.15 0 0 0 -0 0</pose>
          <geometry>
            <mesh>
              <scale>1 1 1</scale>
              <uri>/home/sato/kitani_ws/src/sne_rollover_recovery/tracked_robot/tracked_description/meshes/link1_a.stl</uri>
            </mesh>
          </geometry>
          <surface>
            <contact>
              <ode/>
            </contact>
            <friction>
              <ode>
                <mu>0.2</mu>
                <mu2>0.2</mu2>
              </ode>
            </friction>
            <bounce/>
          </surface>
          <max_contacts>10</max_contacts>
        </collision>
        <visual name='link3_visual'>
          <pose>0.15 0 0 0 -0 0</pose>
          <geometry>
            <mesh>
              <scale>1 1 1</scale>
              <uri>/home/sato/kitani_ws/src/sne_rollover_recovery/tracked_robot/tracked_description/meshes/link1_a.stl</uri>
            </mesh>
          </geometry>
          <material>
            <script>
              <name>Gazebo/Grey</name>
              <uri>__default__</uri>
            </script>
          </material>
        </visual>
        <visual name='link3_visual_camera1'>
          <pose>0 0 0.05 0 -0 0</pose>
          <geometry>
            <box>
              <size>0.02 0.02 0.02</size>
            </box>
          </geometry>
          <material>
            <script>
              <name>Gazebo/Red</name>
              <uri>__default__</uri>
            </script>
          </material>
        </visual>
        <velocity_decay>
          <linear>0</linear>
          <angular>0</angular>
        </velocity_decay>
        <velocity_decay>
          <linear>0</linear>
          <angular>0</angular>
        </velocity_decay>
        <gravity>1</gravity>
        <velocity_decay>
          <linear>0</linear>
          <angular>0</angular>
        </velocity_decay>
        <self_collide>0</self_collide>
        <sensor name='camera1' type='camera'>
          <update_rate>30</update_rate>
          <camera name='head'>
            <horizontal_fov>1.39626</horizontal_fov>
            <image>
              <width>640</width>
              <height>480</height>
              <format>R8G8B8</format>
            </image>
            <clip>
              <near>0.02</near>
              <far>300</far>
            </clip>
            <noise>
              <type>gaussian</type>
              <mean>0</mean>
              <stddev>0.007</stddev>
            </noise>
          </camera>
          <plugin name='camera_controller' filename='libgazebo_ros_camera.so'>
            <alwaysOn>true</alwaysOn>
            <updateRate>0.0</updateRate>
            <cameraName>tracked/camera1</cameraName>
            <imageTopicName>image_raw</imageTopicName>
            <cameraInfoTopicName>camera_info</cameraInfoTopicName>
            <frameName>camera1_link_optical</frameName>
            <hackBaseline>0.0</hackBaseline>
            <distortionK1>0.0</distortionK1>
            <distortionK2>0.0</distortionK2>
            <distortionK3>0.0</distortionK3>
            <distortionT1>0.0</distortionT1>
            <distortionT2>0.0</distortionT2>
            <CxPrime>0</CxPrime>
            <Cx>0.0</Cx>
            <Cy>0.0</Cy>
            <focalLength>0.0</focalLength>
            <robotNamespace>/</robotNamespace>
          </plugin>
          <pose>0 0 0.05 0 -0 0</pose>
        </sensor>
        <kinematic>0</kinematic>
      </link>
      <joint name='m3_2link3' type='revolute'>
        <child>link3</child>
        <parent>link2</parent>
        <axis>
          <xyz>0 1 0</xyz>
          <limit>
            <lower>-1e+16</lower>
            <upper>1e+16</upper>
          </limit>
          <dynamics>
            <damping>0.7</damping>
          </dynamics>
        </axis>
      </joint>
      <link name='m4'>
        <pose>0.6 0 0.125 0 -0 0</pose>
        <inertial>
          <pose>0 0 0 1.5708 -0 0</pose>
          <mass>1</mass>
          <inertia>
            <ixx>0.000907922</ixx>
            <ixy>0</ixy>
            <ixz>0</ixz>
            <iyy>0.00736067</iyy>
            <iyz>0</iyz>
            <izz>0.00671941</izz>
          </inertia>
        </inertial>
        <collision name='m4_collision'>
          <pose>0 0 0 1.5708 -0 0</pose>
          <geometry>
            <mesh>
              <scale>1 1 1</scale>
              <uri>/home/sato/kitani_ws/src/sne_rollover_recovery/tracked_robot/tracked_description/meshes/motor_a.stl</uri>
            </mesh>
          </geometry>
          <surface>
            <contact>
              <ode/>
            </contact>
            <friction>
              <ode>
                <mu>0.2</mu>
                <mu2>0.2</mu2>
              </ode>
            </friction>
            <bounce/>
          </surface>
          <max_contacts>10</max_contacts>
        </collision>
        <visual name='m4_visual'>
          <pose>0 0 0 1.5708 -0 0</pose>
          <geometry>
            <mesh>
              <scale>1 1 1</scale>
              <uri>/home/sato/kitani_ws/src/sne_rollover_recovery/tracked_robot/tracked_description/meshes/motor_a.stl</uri>
            </mesh>
          </geometry>
          <material>
            <script>
              <name>Gazebo/Grey</name>
              <uri>__default__</uri>
            </script>
          </material>
        </visual>
        <visual name='m4_visual_camera2'>
          <pose>0 0 0.05 0 -0 0</pose>
          <geometry>
            <box>
              <size>0.02 0.02 0.02</size>
            </box>
          </geometry>
          <material>
            <script>
              <name>Gazebo/Red</name>
              <uri>__default__</uri>
            </script>
          </material>
        </visual>
        <velocity_decay>
          <linear>0</linear>
          <angular>0</angular>
        </velocity_decay>
        <velocity_decay>
          <linear>0</linear>
          <angular>0</angular>
        </velocity_decay>
        <gravity>1</gravity>
        <velocity_decay>
          <linear>0</linear>
          <angular>0</angular>
        </velocity_decay>
        <self_collide>0</self_collide>
        <sensor name='camera2' type='camera'>
          <update_rate>30</update_rate>
          <camera name='head'>
            <horizontal_fov>1.39626</horizontal_fov>
            <image>
              <width>640</width>
              <height>480</height>
              <format>R8G8B8</format>
            </image>
            <clip>
              <near>0.02</near>
              <far>300</far>
            </clip>
            <noise>
              <type>gaussian</type>
              <mean>0</mean>
              <stddev>0.007</stddev>
            </noise>
          </camera>
          <plugin name='camera_controller' filename='libgazebo_ros_camera.so'>
            <alwaysOn>true</alwaysOn>
            <updateRate>0.0</updateRate>
            <cameraName>tracked/camera2</cameraName>
            <imageTopicName>image_raw</imageTopicName>
            <cameraInfoTopicName>camera_info</cameraInfoTopicName>
            <frameName>camera1_link_optical</frameName>
            <hackBaseline>0.0</hackBaseline>
            <distortionK1>0.0</distortionK1>
            <distortionK2>0.0</distortionK2>
            <distortionK3>0.0</distortionK3>
            <distortionT1>0.0</distortionT1>
            <distortionT2>0.0</distortionT2>
            <CxPrime>0</CxPrime>
            <Cx>0.0</Cx>
            <Cy>0.0</Cy>
            <focalLength>0.0</focalLength>
            <robotNamespace>/</robotNamespace>
          </plugin>
          <pose>0 0 0.05 0 -0 0</pose>
        </sensor>
        <kinematic>0</kinematic>
      </link>
      <joint name='link3_2m4' type='revolute'>
        <child>m4</child>
        <parent>link3</parent>
        <axis>
          <xyz>0 1 0</xyz>
          <limit>
            <lower>-1e+16</lower>
            <upper>1e+16</upper>
          </limit>
          <dynamics>
            <damping>0.7</damping>
          </dynamics>
        </axis>
      </joint>
      <static>0</static>
      <plugin name='gazebo_ros_control' filename='libgazebo_ros_control.so'>
        <robotNamespace>/tracked</robotNamespace>
        <robotSimType>gazebo_ros_control/DefaultRobotHWSim</robotSimType>
      </plugin>
      <pose>0 0 0 0 -0 0</pose>
    </model>
  </world>
</sdf>
