<?xml version="1.0"?>
<!-- Revolute-Revolute Manipulator -->
<robot name="tracked_rviz" xmlns:xacro="http://www.ros.org/wiki/xacro">

  <!-- Constants for robot dimensions -->
  <xacro:property name="PI" value="3.1415926535897931"/>
  <xacro:property name="m_f" value="1" /> <!-- flipper mass -->
  <xacro:property name="m_b" value="30" /> <!-- main mass -->
  <xacro:property name="m_1" value="0.2" /> <!-- motor1 mass -->
  <xacro:property name="m_2" value="1" /> <!-- motor2 mass -->
  <xacro:property name="m_3" value="1" /> <!-- motor3 mass -->
  <xacro:property name="m_4" value="1" /> <!-- motor4 mass -->
  <xacro:property name="m_l2" value="1" /> <!-- l2 mass -->
  <xacro:property name="m_l3" value="1" /> <!-- l3 mass -->
  <xacro:property name="l_fh" value="0.10" /> <!-- flipper height -->
  <xacro:property name="l_fd" value="0.30" /> <!-- flipper depth -->
  <xacro:property name="l_fw" value="0.04" /> <!-- flipper width -->
  <xacro:property name="l_fa" value="0.20" /> <!-- flipper axis width -->
  <xacro:property name="l_bh" value="0.10" /> <!-- main height -->
  <xacro:property name="l_bd" value="0.30" /> <!-- main depth -->
  <xacro:property name="l_bw" value="0.28" /> <!-- main width -->
  <xacro:property name="l_ba" value="0.20" /> <!-- main axis width -->
  <xacro:property name="l_1" value="1" /> <!-- l1 -->
  <xacro:property name="l_2" value="0.30" /> <!-- link2 length -->
  <xacro:property name="l_3" value="0.30" /> <!-- link3 length -->
  <xacro:property name="m_h" value="0.05" /> <!-- motor height -->
  <xacro:property name="width" value="0.05" /> <!-- Square dimensions (widthxwidth) of beams -->
  <xacro:property name="height1" value="2" /> <!-- Link 1 -->
  <xacro:property name="height2" value="0.3" /> <!-- Link 2 -->
  <xacro:property name="height3" value="0.3" /> <!-- Link 3 -->
  <xacro:property name="mass" value="0.8" /> <!-- arbitrary value for mass -->
  <xacro:property name="arm_vel" value="2" /> <!-- velocity limit of arm motor -->
  <xacro:property name="arm_eff" value="2" /> <!-- effort limit of arm motor -->
  <xacro:property name="flipper_vel" value="2" /> <!-- velocity limit of flipper motor -->
  <xacro:property name="flipper_eff" value="2" /> <!-- effort limit of flipper motor -->
  


  <xacro:property name="camera_link" value="0.02" /> <!-- Size of square 'camera' box -->
  <xacro:property name="axel_offset" value="0.05" /> <!-- Space btw top of beam and the each joint -->

  <!-- Import all Gazebo-customization elements, including Gazebo colors -->
<!--  <xacro:include filename="$(find tracked_description)/urdf/rviz/tracked_rviz.gazebo" />-->
  <!-- Import Rviz colors -->
  <xacro:include filename="$(find tracked_description)/urdf/rviz/materials.xacro" />

<!-- arm xacro files-->
<!--You can import one of them-->
  <xacro:include filename="$(find tracked_description)/urdf/rviz/tracked_arm_continuous_position_rviz.xacro" />
<!--  <xacro:include filename="$(find tracked_description)/urdf/rviz/tracked_arm_revolute_position.xacro" />-->
<!--  <xacro:include filename="$(find tracked_description)/urdf/rviz/tracked_arm_revolute_effort.xacro" />-->

<!-- fake crawler xacro files-->
<!-- This model is not completed-->
<!--  <xacro:include filename="$(find tracked_description)/urdf/tracked_wheel.xacro" />-->

  <!-- Used for fixing robot to Gazebo 'base_link' -->
	<link name="world"/>

	<joint name="world2xbase" type="floating">
		<parent link="world"/>
		<child link="xbase"/>
	</joint>


	<link name="xbase">
		<origin xyz="0 0 0" rpy="0 0 0"/>
	</link>

	<joint name="xbase2ybase" type="revolute">
		<parent link="xbase"/>
		<child link="ybase"/>
		<origin rpy="0 0 0" xyz="0 0 0"/>
		<axis xyz="1 0 0"/>
		<limit effort="20" lower="-2.0" upper="2.0" velocity="1"/>
	</joint>

	<link name="ybase">
		<origin xyz="0 0 0" rpy="0 0 0"/>
	</link>


	<joint name="ybase2base" type="revolute">
		<parent link="ybase"/>
		<child link="base"/>
		<origin rpy="0 0 0" xyz="0 0 0"/>
		<axis xyz="0 1 0"/>
		<limit effort="20" lower="-2.0" upper="2.0" velocity="1"/>
	</joint>

  <!-- Base Link -->
  <link name="base">
    <collision>
      <origin xyz="0 0 0" rpy="0 0 0"/>
      <geometry>
	<mesh filename="package://tracked_description/meshes/main_a.stl"/>
      </geometry>
    </collision>

    <visual>
      <origin xyz="0 0 0" rpy="0 0 0"/>
      <geometry>
	<mesh filename="package://tracked_description/meshes/main_a.stl"/>
      </geometry>
      <material name="grey"/>
    </visual>

    <inertial>
      <origin xyz="0 0 0" rpy="0 0 0"/>
      <mass value="${m_b}"/>
      <inertia
	  ixx="0.219237688" ixy="0.0" ixz="0.0"
	  iyy="0.220820092" iyz="0.0"
	  izz="0.393582403"/>
    </inertial>
  </link>

  <link name="robot_origin"/>

  <joint name="base2robot_origin" type="fixed">
    <parent link="base"/>
    <child link="robot_origin"/>
    <origin xyz="0 0 ${-l_bh/2}" rpy="0 0 0"/>
  </joint>


  <joint name="base2FL" type="continuous">
    <parent link="base"/>
    <child link="FL"/>
    <origin xyz="${l_ba/2} ${l_bw/2 + l_fw/2} 0" rpy="0 0 0"/>
    <axis xyz="0 1 0"/>
    <dynamics damping="0.7"/>
  </joint>

  <link name="FL">
    <collision>
      <origin xyz="${l_fa/2} 0 0" rpy="0 0 0"/>
      <geometry>
	<mesh filename="package://tracked_description/meshes/flipper_a.stl"/>
      </geometry>
    </collision>

    <visual>
      <origin xyz="${l_fa/2} 0 0" rpy="0 0 0"/>
      <geometry>
	<mesh filename="package://tracked_description/meshes/flipper_a.stl"/>
      </geometry>
      <material name="blue"/>
    </visual>

    <inertial>
      <origin xyz="${l_fa/2} 0 0" rpy="0 0 0"/>
      <mass value="${m_f}"/>
      <inertia
	  ixx="0.000907922" ixy="0.0" ixz="0.0"
	  iyy="0.007360669" iyz="0.0"
	  izz="0.006719413"/>
    </inertial>
  </link>

  <joint name="base2RL" type="continuous">
    <parent link="base"/>
    <child link="RL"/>
    <origin xyz="${-l_ba/2} ${l_bw/2 + l_fw/2} 0" rpy="0 0 0"/>
    <axis xyz="0 1 0"/>
    <dynamics damping="0.7"/>
  </joint>

  <link name="RL">
    <collision>
      <origin xyz="${-l_fa/2} 0 0" rpy="0 0 0"/>
      <geometry>
	<mesh filename="package://tracked_description/meshes/flipper_a.stl"/>
      </geometry>
    </collision>

    <visual>
      <origin xyz="${-l_fa/2} 0 0" rpy="0 0 0"/>
      <geometry>
	<mesh filename="package://tracked_description/meshes/flipper_a.stl"/>
      </geometry>
      <material name="blue"/>
    </visual>

    <inertial>
      <origin xyz="${-l_fa/2} 0 0" rpy="0 0 0"/>
      <mass value="${m_f}"/>
      <inertia
	  ixx="0.000907922" ixy="0.0" ixz="0.0"
	  iyy="0.007360669" iyz="0.0"
	  izz="0.006719413"/>
    </inertial>
  </link>

  <joint name="base2FR" type="continuous">
    <parent link="base"/>
    <child link="FR"/>
    <origin xyz="${l_ba/2} ${-(l_bw/2 + l_fw/2)} 0" rpy="0 0 0"/>
    <axis xyz="0 1 0"/>
    <dynamics damping="0.7"/>
  </joint>

  <link name="FR">
    <collision>
      <origin xyz="${l_fa/2} 0 0" rpy="0 0 0"/>
      <geometry>
	<mesh filename="package://tracked_description/meshes/flipper_a.stl"/>
      </geometry>
    </collision>

    <visual>
      <origin xyz="${l_fa/2} 0 0" rpy="0 0 0"/>
      <geometry>
	<mesh filename="package://tracked_description/meshes/flipper_a.stl"/>
      </geometry>
      <material name="blue"/>
    </visual>

    <inertial>
      <origin xyz="${l_fa/2} 0 0" rpy="0 0 0"/>
      <mass value="${m_f}"/>
      <inertia
	  ixx="0.000907922" ixy="0.0" ixz="0.0"
	  iyy="0.007360669" iyz="0.0"
	  izz="0.006719413"/>
    </inertial>
  </link>


  <joint name="base2RR" type="continuous">
    <parent link="base"/>
    <child link="RR"/>
    <origin xyz="${-l_ba/2} ${-(l_bw/2 + l_fw/2)} 0" rpy="0 0 0"/>
    <axis xyz="0 1 0"/>
    <dynamics damping="0.7"/>
  </joint>

  <link name="RR">
    <collision>
      <origin xyz="${-l_fa/2} 0 0" rpy="0 0 0"/>
      <geometry>
	<mesh filename="package://tracked_description/meshes/flipper_a.stl"/>
      </geometry>
    </collision>

    <visual>
      <origin xyz="${-l_fa/2} 0 0" rpy="0 0 0"/>
      <geometry>
	<mesh filename="package://tracked_description/meshes/flipper_a.stl"/>
      </geometry>
      <material name="blue"/>
    </visual>

    <inertial>
      <origin xyz="${-l_fa/2} 0 0" rpy="0 0 0"/>
      <mass value="${m_f}"/>
      <inertia
	  ixx="0.000907922" ixy="0.0" ixz="0.0"
	  iyy="0.007360669" iyz="0.0"
	  izz="0.006719413"/>
    </inertial>
  </link>


  <joint name="base2hokuyo" type="fixed">
    <axis xyz="0 1 0" />
    <origin xyz="${l_ba/3+0.02} 0 ${l_bh/2+0.03}" rpy="0 0 0"/>
    <parent link="base"/>
    <child link="hokuyo"/>
  </joint>

  <!-- Hokuyo Laser -->
  <link name="hokuyo">
    <visual>
      <origin xyz="0 0 0" rpy="0 0 0"/>
      <geometry>
        <mesh filename="package://tracked_description/meshes/hokuyo.dae"/>
      </geometry>
    </visual>
  </link>


  <link name="FL_origin"/>

  <joint name="FL2FL_origin" type="fixed">
    <parent link="FL"/>
    <child link="FL_origin"/>
    <origin xyz="${l_fa/2} 0 0" rpy="0 0 0"/>
  </joint>

  <link name="FR_origin"/>

  <joint name="FR2FR_origin" type="fixed">
    <parent link="FR"/>
    <child link="FR_origin"/>
    <origin xyz="${l_fa/2} 0 0" rpy="0 0 0"/>
  </joint>

  <link name="RL_origin"/>

  <joint name="RL2RL_origin" type="fixed">
    <parent link="RL"/>
    <child link="RL_origin"/>
    <origin xyz="${-l_fa/2} 0 0" rpy="0 0 0"/>
  </joint>

  <link name="RR_origin"/>

  <joint name="RR2RR_origin" type="fixed">
    <parent link="RR"/>
    <child link="RR_origin"/>
    <origin xyz="${-l_fa/2} 0 0" rpy="0 0 0"/>
  </joint>


  <link name="FL_tip"/>

  <joint name="FL2FL_tip" type="fixed">
    <parent link="FL"/>
    <child link="FL_tip"/>
    <origin xyz="${l_fa} 0 0" rpy="0 0 0"/>
  </joint>

  <link name="FR_tip"/>

  <joint name="FR2FR_tip" type="fixed">
    <parent link="FR"/>
    <child link="FR_tip"/>
    <origin xyz="${l_fa} 0 0" rpy="0 0 0"/>
  </joint>

  <link name="RL_tip"/>

  <joint name="RL2RL_tip" type="fixed">
    <parent link="RL"/>
    <child link="RL_tip"/>
    <origin xyz="${-l_fa} 0 0" rpy="0 0 0"/>
  </joint>

  <link name="RR_tip"/>

  <joint name="RR2RR_tip" type="fixed">
    <parent link="RR"/>
    <child link="RR_tip"/>
    <origin xyz="${-l_fa} 0 0" rpy="0 0 0"/>
  </joint>

  <link name="right_rollover_axis"/>

  <joint name="robot_origin2right_rollover_axis" type="fixed">
    <parent link="robot_origin"/>
    <child link="right_rollover_axis"/>
    <origin xyz="0 ${-l_bw/2-l_fw} 0" rpy="0 0 0"/>
  </joint>

  <link name="left_rollover_axis"/>

  <joint name="robot_origin2left_rollover_axis" type="fixed">
    <parent link="robot_origin"/>
    <child link="left_rollover_axis"/>
    <origin xyz="0 ${l_bw/2+l_fw} 0" rpy="0 0 0"/>
  </joint>


</robot>
